Rapport d'erreur - 2025-08-22 16:53:53
Message: Erreur lors de la sauvegarde de games.json
Erreur: '_tkinter.tkapp' object has no attribute 'pages_dirty'
Traceback:
Traceback (most recent call last):
  File "c:\Users\Utilisateur\Desktop\jeux en python\lancer1.py", line 704, in save_games
    self._mark_dirty(["games", "main"])
    ~~~~~~~~~~~~~~~~^^^^^^^^^^^^^^^^^^^
  File "c:\Users\Utilisateur\Desktop\jeux en python\lancer1.py", line 470, in _mark_dirty
    if page in self.pages_dirty:
               ^^^^^^^^^^^^^^^^
  File "C:\Users\Utilisateur\AppData\Local\Programs\Python\Python313\Lib\tkinter\__init__.py", line 2552, in __getattr__
    return getattr(self.tk, attr)
AttributeError: '_tkinter.tkapp' object has no attribute 'pages_dirty'
----------------------------------------
Rapport d'erreur - 2025-08-22 16:53:54
Message: Crash majeur de l'application
Erreur: 'Frame' object has no attribute 'attributes'
Traceback:
Traceback (most recent call last):
  File "c:\Users\Utilisateur\Desktop\jeux en python\lancer1.py", line 2350, in main
    app = GameLauncher()
  File "c:\Users\Utilisateur\Desktop\jeux en python\lancer1.py", line 374, in __init__
    self.show_page("main")
    ~~~~~~~~~~~~~~^^^^^^^^
  File "c:\Users\Utilisateur\Desktop\jeux en python\lancer1.py", line 840, in show_page
    self._transition_to_page(target_frame)
    ~~~~~~~~~~~~~~~~~~~~~~~~^^^^^^^^^^^^^^
  File "c:\Users\Utilisateur\Desktop\jeux en python\lancer1.py", line 895, in _transition_to_page
    fade_in()
    ~~~~~~~^^
  File "c:\Users\Utilisateur\Desktop\jeux en python\lancer1.py", line 853, in fade_in
    target_frame.attributes("-alpha", 0.0)
    ^^^^^^^^^^^^^^^^^^^^^^^
AttributeError: 'Frame' object has no attribute 'attributes'
----------------------------------------
Rapport d'erreur - 2025-08-22 16:56:14
Message: Erreur lors de la sauvegarde de games.json
Erreur: '_tkinter.tkapp' object has no attribute 'pages_dirty'
Traceback:
Traceback (most recent call last):
  File "c:\Users\Utilisateur\Desktop\jeux en python\lancer1.py", line 657, in save_games
    self._mark_dirty(["games", "main"])
    ~~~~~~~~~~~~~~~~^^^^^^^^^^^^^^^^^^^
  File "c:\Users\Utilisateur\Desktop\jeux en python\lancer1.py", line 423, in _mark_dirty
    if page in self.pages_dirty:
               ^^^^^^^^^^^^^^^^
  File "C:\Users\Utilisateur\AppData\Local\Programs\Python\Python313\Lib\tkinter\__init__.py", line 2552, in __getattr__
    return getattr(self.tk, attr)
AttributeError: '_tkinter.tkapp' object has no attribute 'pages_dirty'
----------------------------------------
Rapport d'erreur - 2025-08-22 16:59:56
Message: Erreur lors de la sauvegarde de games.json
Erreur: '_tkinter.tkapp' object has no attribute 'pages_dirty'
Traceback:
Traceback (most recent call last):
  File "c:\Users\Utilisateur\Desktop\jeux en python\lancer1.py", line 656, in save_games
    self._mark_dirty(["games", "main"])
    ~~~~~~~~~~~~~~~~^^^^^^^^^^^^^^^^^^^
  File "c:\Users\Utilisateur\Desktop\jeux en python\lancer1.py", line 423, in _mark_dirty
    if page in self.pages_dirty:
               ^^^^^^^^^^^^^^^^
  File "C:\Users\Utilisateur\AppData\Local\Programs\Python\Python313\Lib\tkinter\__init__.py", line 2552, in __getattr__
    return getattr(self.tk, attr)
AttributeError: '_tkinter.tkapp' object has no attribute 'pages_dirty'
----------------------------------------
Rapport d'erreur - 2025-08-22 17:03:37
Message: Erreur lors de la sauvegarde de games.json
Erreur: '_tkinter.tkapp' object has no attribute 'pages_dirty'
Traceback:
Traceback (most recent call last):
  File "c:\Users\Utilisateur\Desktop\jeux en python\lancer1.py", line 672, in save_games
    self._mark_dirty(["games", "main"])
    ~~~~~~~~~~~~~~~~^^^^^^^^^^^^^^^^^^^
  File "c:\Users\Utilisateur\Desktop\jeux en python\lancer1.py", line 439, in _mark_dirty
    if page in self.pages_dirty:
               ^^^^^^^^^^^^^^^^
  File "C:\Users\Utilisateur\AppData\Local\Programs\Python\Python313\Lib\tkinter\__init__.py", line 2552, in __getattr__
    return getattr(self.tk, attr)
AttributeError: '_tkinter.tkapp' object has no attribute 'pages_dirty'
----------------------------------------
Rapport d'erreur - 2025-08-22 17:03:38
Message: Crash majeur de l'application
Erreur: '_tkinter.tkapp' object has no attribute 'clear_filters'
Traceback:
Traceback (most recent call last):
  File "c:\Users\Utilisateur\Desktop\jeux en python\lancer1.py", line 2332, in main
    app = GameLauncher()
  File "c:\Users\Utilisateur\Desktop\jeux en python\lancer1.py", line 323, in __init__
    self.create_games_page()
    ~~~~~~~~~~~~~~~~~~~~~~^^
  File "c:\Users\Utilisateur\Desktop\jeux en python\lancer1.py", line 1298, in create_games_page
    clear_btn = ttk.Button(top_toolbar, text="X", command=self.clear_filters, bootstyle="danger-link", width=2)
                                                          ^^^^^^^^^^^^^^^^^^
  File "C:\Users\Utilisateur\AppData\Local\Programs\Python\Python313\Lib\tkinter\__init__.py", line 2552, in __getattr__
    return getattr(self.tk, attr)
AttributeError: '_tkinter.tkapp' object has no attribute 'clear_filters'
----------------------------------------
Rapport d'erreur - 2025-08-22 17:05:49
Message: Erreur lors de la sauvegarde de games.json
Erreur: '_tkinter.tkapp' object has no attribute 'pages_dirty'
Traceback:
Traceback (most recent call last):
  File "c:\Users\Utilisateur\Desktop\jeux en python\lancer1.py", line 658, in save_games
    self._mark_dirty(["games", "main"])
    ~~~~~~~~~~~~~~~~^^^^^^^^^^^^^^^^^^^
  File "c:\Users\Utilisateur\Desktop\jeux en python\lancer1.py", line 425, in _mark_dirty
    if page in self.pages_dirty:
               ^^^^^^^^^^^^^^^^
  File "C:\Users\Utilisateur\AppData\Local\Programs\Python\Python313\Lib\tkinter\__init__.py", line 2552, in __getattr__
    return getattr(self.tk, attr)
AttributeError: '_tkinter.tkapp' object has no attribute 'pages_dirty'
----------------------------------------
Rapport d'erreur - 2025-08-22 17:05:50
Message: Crash majeur de l'application
Erreur: '_tkinter.tkapp' object has no attribute 'clear_filters'
Traceback:
Traceback (most recent call last):
  File "c:\Users\Utilisateur\Desktop\jeux en python\lancer1.py", line 2317, in main
    app = GameLauncher()
  File "c:\Users\Utilisateur\Desktop\jeux en python\lancer1.py", line 298, in __init__
    self.create_games_page()
    ~~~~~~~~~~~~~~~~~~~~~~^^
  File "c:\Users\Utilisateur\Desktop\jeux en python\lancer1.py", line 1283, in create_games_page
    clear_btn = ttk.Button(top_toolbar, text="X", command=self.clear_filters, bootstyle="danger-link", width=2)
                                                          ^^^^^^^^^^^^^^^^^^
  File "C:\Users\Utilisateur\AppData\Local\Programs\Python\Python313\Lib\tkinter\__init__.py", line 2552, in __getattr__
    return getattr(self.tk, attr)
AttributeError: '_tkinter.tkapp' object has no attribute 'clear_filters'
----------------------------------------
Rapport d'erreur - 2025-08-22 17:09:35
Message: Crash majeur de l'application
Erreur: '_tkinter.tkapp' object has no attribute 'get_games_folder'
Traceback:
Traceback (most recent call last):
  File "c:\Users\Utilisateur\Desktop\jeux en python\lancer1.py", line 2185, in main
    app = GameLauncher()
  File "c:\Users\Utilisateur\Desktop\jeux en python\lancer1.py", line 236, in __init__
    self.scan_for_games()
    ~~~~~~~~~~~~~~~~~~~^^
  File "c:\Users\Utilisateur\Desktop\jeux en python\lancer1.py", line 677, in scan_for_games
    folder = self.get_games_folder()
             ^^^^^^^^^^^^^^^^^^^^^
  File "C:\Users\Utilisateur\AppData\Local\Programs\Python\Python313\Lib\tkinter\__init__.py", line 2552, in __getattr__
    return getattr(self.tk, attr)
AttributeError: '_tkinter.tkapp' object has no attribute 'get_games_folder'
----------------------------------------
Rapport d'erreur - 2025-08-22 17:12:32
Message: Crash majeur de l'application
Erreur: property 'style' of 'GameLauncher' object has no setter
Traceback:
Traceback (most recent call last):
  File "c:\Users\Utilisateur\Desktop\jeux en python\lancer1.py", line 1962, in main
    app = GameLauncher()
  File "c:\Users\Utilisateur\Desktop\jeux en python\lancer1.py", line 228, in __init__
    self.style = ttk.Style() # Le style doit être initialisé tôt
    ^^^^^^^^^^
AttributeError: property 'style' of 'GameLauncher' object has no setter
----------------------------------------
Rapport d'erreur - 2025-08-22 17:14:17
Message: Crash majeur de l'application
Erreur: property 'style' of 'GameLauncher' object has no setter
Traceback:
Traceback (most recent call last):
  File "c:\Users\Utilisateur\Desktop\jeux en python\lancer1.py", line 896, in main
    app = GameLauncher()
  File "c:\Users\Utilisateur\Desktop\jeux en python\lancer1.py", line 228, in __init__
    self.style = ttk.Style() # Le style doit être initialisé tôt
    ^^^^^^^^^^
AttributeError: property 'style' of 'GameLauncher' object has no setter
----------------------------------------
Rapport d'erreur - 2025-08-22 17:19:56
Message: Crash majeur de l'application
Erreur: property 'style' of 'GameLauncher' object has no setter
Traceback:
Traceback (most recent call last):
  File "c:\Users\Utilisateur\Desktop\jeux en python\lancer1.py", line 892, in main
    app = GameLauncher()
  File "c:\Users\Utilisateur\Desktop\jeux en python\lancer1.py", line 206, in __init__
    self.style = ttk.Style() # Le style doit être initialisé tôt
    ^^^^^^^^^^
AttributeError: property 'style' of 'GameLauncher' object has no setter
----------------------------------------
Rapport d'erreur - 2025-08-22 17:25:25
Message: Crash majeur de l'application
Erreur: property 'style' of 'GameLauncher' object has no setter
Traceback:
Traceback (most recent call last):
  File "c:\Users\Utilisateur\Desktop\jeux en python\lancer1.py", line 892, in main
    app = GameLauncher()
  File "c:\Users\Utilisateur\Desktop\jeux en python\lancer1.py", line 206, in __init__
    self.style = ttk.Style() # Le style doit être initialisé tôt
    ^^^^^^^^^^
AttributeError: property 'style' of 'GameLauncher' object has no setter
----------------------------------------
Rapport d'erreur - 2025-08-22 17:25:28
Message: Crash majeur de l'application
Erreur: property 'style' of 'GameLauncher' object has no setter
Traceback:
Traceback (most recent call last):
  File "c:\Users\Utilisateur\Desktop\jeux en python\lancer1.py", line 892, in main
    app = GameLauncher()
  File "c:\Users\Utilisateur\Desktop\jeux en python\lancer1.py", line 206, in __init__
    self.style = ttk.Style() # Le style doit être initialisé tôt
    ^^^^^^^^^^
AttributeError: property 'style' of 'GameLauncher' object has no setter
----------------------------------------
Rapport d'erreur - 2025-08-22 17:33:33
Message: Crash majeur de l'application
Erreur: property 'style' of 'GameLauncher' object has no setter
Traceback:
Traceback (most recent call last):
  File "c:\Users\Utilisateur\Desktop\jeux en python\lancer1.py", line 1189, in main
    app = GameLauncher()
  File "c:\Users\Utilisateur\Desktop\jeux en python\lancer1.py", line 186, in __init__
    self.style = ttk.Style()
    ^^^^^^^^^^
AttributeError: property 'style' of 'GameLauncher' object has no setter
----------------------------------------
Rapport d'erreur - 2025-08-22 17:35:40
Message: Crash majeur de l'application
Erreur: property 'style' of 'GameLauncher' object has no setter
Traceback:
Traceback (most recent call last):
  File "c:\Users\Utilisateur\Desktop\jeux en python\lancer1.py", line 1189, in main
    app = GameLauncher()
  File "c:\Users\Utilisateur\Desktop\jeux en python\lancer1.py", line 186, in __init__
    self.style = ttk.Style()
    ^^^^^^^^^^
AttributeError: property 'style' of 'GameLauncher' object has no setter
----------------------------------------
Rapport d'erreur - 2025-08-22 17:38:02
Message: Crash majeur de l'application
Erreur: property 'style' of 'GameLauncher' object has no setter
Traceback:
Traceback (most recent call last):
  File "c:\Users\Utilisateur\Desktop\jeux en python\lancer1.py", line 1192, in main
    app = GameLauncher()
  File "c:\Users\Utilisateur\Desktop\jeux en python\lancer1.py", line 186, in __init__
    self.style = ttk.Style()
    ^^^^^^^^^^
AttributeError: property 'style' of 'GameLauncher' object has no setter
----------------------------------------
Rapport d'erreur - 2025-08-22 17:39:18
Message: Crash majeur de l'application
Erreur: property 'style' of 'GameLauncher' object has no setter
Traceback:
Traceback (most recent call last):
  File "c:\Users\Utilisateur\Desktop\jeux en python\lancer1.py", line 1196, in main
    app = GameLauncher()
  File "c:\Users\Utilisateur\Desktop\jeux en python\lancer1.py", line 186, in __init__
    self.style = ttk.Style()
    ^^^^^^^^^^
AttributeError: property 'style' of 'GameLauncher' object has no setter
----------------------------------------
Rapport d'erreur - 2025-08-22 17:40:39
Message: Erreur lors de la sauvegarde de games.json
Erreur: '_tkinter.tkapp' object has no attribute 'pages_dirty'
Traceback:
Traceback (most recent call last):
  File "c:\Users\Utilisateur\Desktop\jeux en python\lancer1.py", line 883, in save_games
    self._mark_dirty(["games", "main"])
    ~~~~~~~~~~~~~~~~^^^^^^^^^^^^^^^^^^^
  File "c:\Users\Utilisateur\Desktop\jeux en python\lancer1.py", line 1120, in _mark_dirty
    if page in self.pages_dirty:
               ^^^^^^^^^^^^^^^^
  File "C:\Users\Utilisateur\AppData\Local\Programs\Python\Python313\Lib\tkinter\__init__.py", line 2552, in __getattr__
    return getattr(self.tk, attr)
AttributeError: '_tkinter.tkapp' object has no attribute 'pages_dirty'
----------------------------------------
Rapport d'erreur - 2025-08-22 18:03:45
Message: Erreur lors de la sauvegarde de games.json
Erreur: '_tkinter.tkapp' object has no attribute 'pages_dirty'
Traceback:
Traceback (most recent call last):
  File "c:\Users\Utilisateur\Desktop\jeux en python\lancer1.py", line 899, in save_games
    self._mark_dirty(["games", "main"])
    ~~~~~~~~~~~~~~~~^^^^^^^^^^^^^^^^^^^
  File "c:\Users\Utilisateur\Desktop\jeux en python\lancer1.py", line 1222, in _mark_dirty
    if page in self.pages_dirty:
               ^^^^^^^^^^^^^^^^
  File "C:\Users\Utilisateur\AppData\Local\Programs\Python\Python313\Lib\tkinter\__init__.py", line 2552, in __getattr__
    return getattr(self.tk, attr)
AttributeError: '_tkinter.tkapp' object has no attribute 'pages_dirty'
----------------------------------------
Rapport d'erreur - 2025-08-22 18:03:45
Message: Erreur lors de la sauvegarde de games.json
Erreur: '_tkinter.tkapp' object has no attribute 'pages_dirty'
Traceback:
Traceback (most recent call last):
  File "c:\Users\Utilisateur\Desktop\jeux en python\lancer1.py", line 899, in save_games
    self._mark_dirty(["games", "main"])
    ~~~~~~~~~~~~~~~~^^^^^^^^^^^^^^^^^^^
  File "c:\Users\Utilisateur\Desktop\jeux en python\lancer1.py", line 1222, in _mark_dirty
    if page in self.pages_dirty:
               ^^^^^^^^^^^^^^^^
  File "C:\Users\Utilisateur\AppData\Local\Programs\Python\Python313\Lib\tkinter\__init__.py", line 2552, in __getattr__
    return getattr(self.tk, attr)
AttributeError: '_tkinter.tkapp' object has no attribute 'pages_dirty'
----------------------------------------
Rapport d'erreur - 2025-08-22 18:37:20
Message: Erreur lors de la sauvegarde de games.json
Erreur: '_tkinter.tkapp' object has no attribute 'pages_dirty'
Traceback:
Traceback (most recent call last):
  File "c:\Users\Utilisateur\Desktop\jeux en python\lancer1.py", line 871, in save_games
    self._mark_dirty(["games", "main"])
    ~~~~~~~~~~~~~~~~^^^^^^^^^^^^^^^^^^^
  File "c:\Users\Utilisateur\Desktop\jeux en python\lancer1.py", line 1194, in _mark_dirty
    if page in self.pages_dirty:
               ^^^^^^^^^^^^^^^^
  File "C:\Users\Utilisateur\AppData\Local\Programs\Python\Python313\Lib\tkinter\__init__.py", line 2552, in __getattr__
    return getattr(self.tk, attr)
AttributeError: '_tkinter.tkapp' object has no attribute 'pages_dirty'
----------------------------------------
Rapport d'erreur - 2025-08-23 12:02:28
Message: L'application a rencontré une erreur fatale et va se fermer.
Erreur: '_tkinter.tkapp' object has no attribute 'pages_dirty'
Traceback:
Traceback (most recent call last):
  File "c:\Users\Utilisateur\Desktop\jeux en python\lancer1.py", line 1440, in <module>
    app = GameLauncher()
  File "c:\Users\Utilisateur\Desktop\jeux en python\lancer1.py", line 198, in __init__
    self.save_games()
    ~~~~~~~~~~~~~~~^^
  File "c:\Users\Utilisateur\Desktop\jeux en python\lancer1.py", line 966, in save_games
    self._mark_dirty(["games", "main"])
    ~~~~~~~~~~~~~~~~^^^^^^^^^^^^^^^^^^^
  File "c:\Users\Utilisateur\Desktop\jeux en python\lancer1.py", line 1369, in _mark_dirty
    if page in self.pages_dirty:
               ^^^^^^^^^^^^^^^^
  File "C:\Users\Utilisateur\AppData\Local\Programs\Python\Python313\Lib\tkinter\__init__.py", line 2552, in __getattr__
    return getattr(self.tk, attr)
AttributeError: '_tkinter.tkapp' object has no attribute 'pages_dirty'
----------------------------------------
Rapport d'erreur - 2025-08-23 12:02:49
Message: L'application a rencontré une erreur fatale et va se fermer.
Erreur: '_tkinter.tkapp' object has no attribute 'pages_dirty'
Traceback:
Traceback (most recent call last):
  File "c:\Users\Utilisateur\Desktop\jeux en python\lancer1.py", line 1440, in <module>
    app = GameLauncher()
  File "c:\Users\Utilisateur\Desktop\jeux en python\lancer1.py", line 198, in __init__
    self.save_games()
    ~~~~~~~~~~~~~~~^^
  File "c:\Users\Utilisateur\Desktop\jeux en python\lancer1.py", line 966, in save_games
    self._mark_dirty(["games", "main"])
    ~~~~~~~~~~~~~~~~^^^^^^^^^^^^^^^^^^^
  File "c:\Users\Utilisateur\Desktop\jeux en python\lancer1.py", line 1369, in _mark_dirty
    if page in self.pages_dirty:
               ^^^^^^^^^^^^^^^^
  File "C:\Users\Utilisateur\AppData\Local\Programs\Python\Python313\Lib\tkinter\__init__.py", line 2552, in __getattr__
    return getattr(self.tk, attr)
AttributeError: '_tkinter.tkapp' object has no attribute 'pages_dirty'
----------------------------------------
Rapport d'erreur - 2025-08-23 12:10:12
Message: L'application a rencontré une erreur fatale et va se fermer.
Erreur: '_tkinter.tkapp' object has no attribute 'scan_button'
Traceback:
Traceback (most recent call last):
  File "c:\Users\Utilisateur\Desktop\jeux en python\lancer1.py", line 1836, in <module>
    app = GameLauncher()
  File "c:\Users\Utilisateur\Desktop\jeux en python\lancer1.py", line 233, in __init__
    self.scan_for_games()
    ~~~~~~~~~~~~~~~~~~~^^
  File "c:\Users\Utilisateur\Desktop\jeux en python\lancer1.py", line 1294, in scan_for_games
    self.after(0, self.scan_button.config, {"text": "Scan en cours...", "state": "disabled"})
                  ^^^^^^^^^^^^^^^^
  File "C:\Users\Utilisateur\AppData\Local\Programs\Python\Python313\Lib\tkinter\__init__.py", line 2552, in __getattr__
    return getattr(self.tk, attr)
AttributeError: '_tkinter.tkapp' object has no attribute 'scan_button'
----------------------------------------
Rapport d'erreur - 2025-08-23 14:10:06
Message: L'application a rencontré une erreur fatale et va se fermer.
Erreur: name 'sf' is not defined
Traceback:
Traceback (most recent call last):
  File "c:\Users\Utilisateur\Desktop\jeux en python\lancer1.py", line 1968, in <module>
    app = GameLauncher()
  File "c:\Users\Utilisateur\Desktop\jeux en python\lancer1.py", line 293, in __init__
    self.create_settings_page()
    ~~~~~~~~~~~~~~~~~~~~~~~~~^^
  File "c:\Users\Utilisateur\Desktop\jeux en python\lancer1.py", line 641, in create_settings_page
    container = sf.container
                ^^
NameError: name 'sf' is not defined
----------------------------------------
Rapport d'erreur - 2025-08-23 14:11:16
Message: L'application a rencontré une erreur fatale et va se fermer.
Erreur: '_tkinter.tkapp' object has no attribute '_on_global_mouse_wheel'
Traceback:
Traceback (most recent call last):
  File "c:\Users\Utilisateur\Desktop\jeux en python\lancer1.py", line 1968, in <module>
    app = GameLauncher()
  File "c:\Users\Utilisateur\Desktop\jeux en python\lancer1.py", line 307, in __init__
    self.bind_all("<MouseWheel>", self._on_global_mouse_wheel) # Global mouse wheel binding
                                  ^^^^^^^^^^^^^^^^^^^^^^^^^^^
  File "C:\Users\Utilisateur\AppData\Local\Programs\Python\Python313\Lib\tkinter\__init__.py", line 2552, in __getattr__
    return getattr(self.tk, attr)
AttributeError: '_tkinter.tkapp' object has no attribute '_on_global_mouse_wheel'
----------------------------------------
Rapport d'erreur - 2025-08-23 14:14:13
Message: L'application a rencontré une erreur fatale et va se fermer.
Erreur: 'ScrolledFrame' object has no attribute 'bind_mouse_wheel'
Traceback:
Traceback (most recent call last):
  File "c:\Users\Utilisateur\Desktop\jeux en python\lancer1.py", line 1976, in <module>
    app = GameLauncher()
  File "c:\Users\Utilisateur\Desktop\jeux en python\lancer1.py", line 293, in __init__
    self.create_settings_page()
    ~~~~~~~~~~~~~~~~~~~~~~~~~^^
  File "c:\Users\Utilisateur\Desktop\jeux en python\lancer1.py", line 701, in create_settings_page
    self.settings_scrolled_frame.bind_mouse_wheel(container)
    ^^^^^^^^^^^^^^^^^^^^^^^^^^^^^^^^^^^^^^^^^^^^^
AttributeError: 'ScrolledFrame' object has no attribute 'bind_mouse_wheel'
----------------------------------------
Rapport d'erreur - 2025-08-23 14:19:04
Message: L'application a rencontré une erreur fatale et va se fermer.
Erreur: 'Frame' object has no attribute 'attributes'
Traceback:
Traceback (most recent call last):
  File "c:\Users\Utilisateur\Desktop\jeux en python\lancer1.py", line 2029, in <module>
    app = GameLauncher()
  File "c:\Users\Utilisateur\Desktop\jeux en python\lancer1.py", line 306, in __init__
    self.show_page("main")
    ~~~~~~~~~~~~~~^^^^^^^^
  File "c:\Users\Utilisateur\Desktop\jeux en python\lancer1.py", line 1152, in show_page
    self._transition_to_page(target_frame)
    ~~~~~~~~~~~~~~~~~~~~~~~~^^^^^^^^^^^^^^
  File "c:\Users\Utilisateur\Desktop\jeux en python\lancer1.py", line 373, in _transition_to_page
    target_frame.attributes("-alpha", 0.0)
    ^^^^^^^^^^^^^^^^^^^^^^^
AttributeError: 'Frame' object has no attribute 'attributes'
----------------------------------------
Rapport d'erreur - 2025-08-23 14:19:55
Message: L'application a rencontré une erreur fatale et va se fermer.
Erreur: unknown option "-labeltext"
Traceback:
Traceback (most recent call last):
  File "c:\Users\Utilisateur\Desktop\jeux en python\lancer1.py", line 2018, in <module>
    app = GameLauncher()
  File "c:\Users\Utilisateur\Desktop\jeux en python\lancer1.py", line 310, in __init__
    self.create_pro_page()
    ~~~~~~~~~~~~~~~~~~~~^^
  File "c:\Users\Utilisateur\Desktop\jeux en python\lancer1.py", line 841, in create_pro_page
    self.pro_stats_ach_meter = Meter(
                               ~~~~~^
        master=ach_frame,
        ^^^^^^^^^^^^^^^^^
    ...<7 lines>...
        interactive=False,
        ^^^^^^^^^^^^^^^^^^
    )
    ^
  File "C:\Users\Utilisateur\AppData\Local\Programs\Python\Python313\Lib\site-packages\ttkbootstrap\widgets.py", line 1117, in __init__
    super().__init__(master=master, **kwargs)
    ~~~~~~~~~~~~~~~~^^^^^^^^^^^^^^^^^^^^^^^^^
  File "C:\Users\Utilisateur\AppData\Local\Programs\Python\Python313\Lib\site-packages\ttkbootstrap\style.py", line 5187, in __init__
    func(self, *args, **kwargs)
    ~~~~^^^^^^^^^^^^^^^^^^^^^^^
  File "C:\Users\Utilisateur\AppData\Local\Programs\Python\Python313\Lib\tkinter\ttk.py", line 720, in __init__
    Widget.__init__(self, master, "ttk::frame", kw)
    ~~~~~~~~~~~~~~~^^^^^^^^^^^^^^^^^^^^^^^^^^^^^^^^
  File "C:\Users\Utilisateur\AppData\Local\Programs\Python\Python313\Lib\tkinter\ttk.py", line 534, in __init__
    tkinter.Widget.__init__(self, master, widgetname, kw=kw)
    ~~~~~~~~~~~~~~~~~~~~~~~^^^^^^^^^^^^^^^^^^^^^^^^^^^^^^^^^
  File "C:\Users\Utilisateur\AppData\Local\Programs\Python\Python313\Lib\tkinter\__init__.py", line 2780, in __init__
    self.tk.call(
    ~~~~~~~~~~~~^
        (widgetName, self._w) + extra + self._options(cnf))
        ^^^^^^^^^^^^^^^^^^^^^^^^^^^^^^^^^^^^^^^^^^^^^^^^^^^
_tkinter.TclError: unknown option "-labeltext"
----------------------------------------
Rapport d'erreur - 2025-08-23 14:44:25
Message: L'application a rencontré une erreur fatale et va se fermer.
Erreur: type object 'StyleBuilderTTK' has no attribute 'create_round_button_style'
Traceback:
Traceback (most recent call last):
  File "c:\Users\Utilisateur\Desktop\jeux en python\lancer1.py", line 2053, in <module>
    app = GameLauncher()
  File "c:\Users\Utilisateur\Desktop\jeux en python\lancer1.py", line 321, in __init__
    self.create_settings_page()
    ~~~~~~~~~~~~~~~~~~~~~~~~~^^
  File "c:\Users\Utilisateur\Desktop\jeux en python\lancer1.py", line 773, in create_settings_page
    ttk.Button(maintenance_frame, text=text, command=cmd, bootstyle="secondary-round").grid(row=row, column=col, sticky="ew", padx=10, pady=5)
    ~~~~~~~~~~^^^^^^^^^^^^^^^^^^^^^^^^^^^^^^^^^^^^^^^^^^^^^^^^^^^^^^^^^^^^^^^^^^^^^^^^
  File "C:\Users\Utilisateur\AppData\Local\Programs\Python\Python313\Lib\site-packages\ttkbootstrap\style.py", line 5201, in __init__
    ttkstyle = Bootstyle.update_ttk_widget_style(
        self, bootstyle, **kwargs
    )
  File "C:\Users\Utilisateur\AppData\Local\Programs\Python\Python313\Lib\site-packages\ttkbootstrap\style.py", line 5295, in update_ttk_widget_style
    builder_method = builder.name_to_method(method_name)
  File "C:\Users\Utilisateur\AppData\Local\Programs\Python\Python313\Lib\site-packages\ttkbootstrap\style.py", line 1241, in name_to_method
    func = getattr(StyleBuilderTTK, method_name)
AttributeError: type object 'StyleBuilderTTK' has no attribute 'create_round_button_style'. Did you mean: 'create_link_button_style'?
----------------------------------------
Rapport d'erreur - 2025-08-23 15:09:24
Message: L'application a rencontré une erreur fatale et va se fermer.
Erreur: type object 'StyleBuilderTTK' has no attribute 'create_round_button_style'
Traceback:
Traceback (most recent call last):
  File "c:\Users\Utilisateur\Desktop\jeux en python\lancer1.py", line 2077, in <module>
    app = GameLauncher()
  File "c:\Users\Utilisateur\Desktop\jeux en python\lancer1.py", line 323, in __init__
    self.create_settings_page()
    ~~~~~~~~~~~~~~~~~~~~~~~~~^^
  File "c:\Users\Utilisateur\Desktop\jeux en python\lancer1.py", line 783, in create_settings_page
    ttk.Button(maintenance_frame, text=text, command=cmd, bootstyle="secondary,round").grid(row=row, column=col, sticky="ew", padx=10, pady=5)
    ~~~~~~~~~~^^^^^^^^^^^^^^^^^^^^^^^^^^^^^^^^^^^^^^^^^^^^^^^^^^^^^^^^^^^^^^^^^^^^^^^^
  File "C:\Users\Utilisateur\AppData\Local\Programs\Python\Python313\Lib\site-packages\ttkbootstrap\style.py", line 5201, in __init__
    ttkstyle = Bootstyle.update_ttk_widget_style(
        self, bootstyle, **kwargs
    )
  File "C:\Users\Utilisateur\AppData\Local\Programs\Python\Python313\Lib\site-packages\ttkbootstrap\style.py", line 5295, in update_ttk_widget_style
    builder_method = builder.name_to_method(method_name)
  File "C:\Users\Utilisateur\AppData\Local\Programs\Python\Python313\Lib\site-packages\ttkbootstrap\style.py", line 1241, in name_to_method
    func = getattr(StyleBuilderTTK, method_name)
AttributeError: type object 'StyleBuilderTTK' has no attribute 'create_round_button_style'. Did you mean: 'create_link_button_style'?
----------------------------------------
Rapport d'erreur - 2025-08-23 15:13:34
Message: L'application a rencontré une erreur fatale et va se fermer.
Erreur: type object 'StyleBuilderTTK' has no attribute 'create_round_button_style'
Traceback:
Traceback (most recent call last):
  File "c:\Users\Utilisateur\Desktop\jeux en python\lancer1.py", line 2084, in <module>
    app = GameLauncher()
  File "c:\Users\Utilisateur\Desktop\jeux en python\lancer1.py", line 323, in __init__
    self.create_settings_page()
    ~~~~~~~~~~~~~~~~~~~~~~~~~^^
  File "c:\Users\Utilisateur\Desktop\jeux en python\lancer1.py", line 787, in create_settings_page
    ttk.Button(maintenance_frame, text=text, command=cmd, bootstyle="secondary-round").grid(row=row, column=col, sticky="ew", padx=10, pady=5)
    ~~~~~~~~~~^^^^^^^^^^^^^^^^^^^^^^^^^^^^^^^^^^^^^^^^^^^^^^^^^^^^^^^^^^^^^^^^^^^^^^^^
  File "C:\Users\Utilisateur\AppData\Local\Programs\Python\Python313\Lib\site-packages\ttkbootstrap\style.py", line 5201, in __init__
    ttkstyle = Bootstyle.update_ttk_widget_style(
        self, bootstyle, **kwargs
    )
  File "C:\Users\Utilisateur\AppData\Local\Programs\Python\Python313\Lib\site-packages\ttkbootstrap\style.py", line 5295, in update_ttk_widget_style
    builder_method = builder.name_to_method(method_name)
  File "C:\Users\Utilisateur\AppData\Local\Programs\Python\Python313\Lib\site-packages\ttkbootstrap\style.py", line 1241, in name_to_method
    func = getattr(StyleBuilderTTK, method_name)
AttributeError: type object 'StyleBuilderTTK' has no attribute 'create_round_button_style'. Did you mean: 'create_link_button_style'?
----------------------------------------
Rapport d'erreur - 2025-08-23 15:15:30
Message: L'application a rencontré une erreur fatale et va se fermer.
Erreur: type object 'StyleBuilderTTK' has no attribute 'create_round_button_style'
Traceback:
Traceback (most recent call last):
  File "c:\Users\Utilisateur\Desktop\jeux en python\lancer1.py", line 2084, in <module>
    app = GameLauncher()
  File "c:\Users\Utilisateur\Desktop\jeux en python\lancer1.py", line 323, in __init__
    self.create_settings_page()
    ~~~~~~~~~~~~~~~~~~~~~~~~~^^
  File "c:\Users\Utilisateur\Desktop\jeux en python\lancer1.py", line 787, in create_settings_page
    ttk.Button(maintenance_frame, text=text, command=cmd, bootstyle="secondary,round").grid(row=row, column=col, sticky="ew", padx=10, pady=5)
    ~~~~~~~~~~^^^^^^^^^^^^^^^^^^^^^^^^^^^^^^^^^^^^^^^^^^^^^^^^^^^^^^^^^^^^^^^^^^^^^^^^
  File "C:\Users\Utilisateur\AppData\Local\Programs\Python\Python313\Lib\site-packages\ttkbootstrap\style.py", line 5201, in __init__
    ttkstyle = Bootstyle.update_ttk_widget_style(
        self, bootstyle, **kwargs
    )
  File "C:\Users\Utilisateur\AppData\Local\Programs\Python\Python313\Lib\site-packages\ttkbootstrap\style.py", line 5295, in update_ttk_widget_style
    builder_method = builder.name_to_method(method_name)
  File "C:\Users\Utilisateur\AppData\Local\Programs\Python\Python313\Lib\site-packages\ttkbootstrap\style.py", line 1241, in name_to_method
    func = getattr(StyleBuilderTTK, method_name)
AttributeError: type object 'StyleBuilderTTK' has no attribute 'create_round_button_style'. Did you mean: 'create_link_button_style'?
----------------------------------------
Rapport d'erreur - 2025-08-23 15:18:07
Message: L'application a rencontré une erreur fatale et va se fermer.
Erreur: type object 'StyleBuilderTTK' has no attribute 'create_round_button_style'
Traceback:
Traceback (most recent call last):
  File "c:\Users\Utilisateur\Desktop\jeux en python\lancer1.py", line 2084, in <module>
    app = GameLauncher()
  File "c:\Users\Utilisateur\Desktop\jeux en python\lancer1.py", line 323, in __init__
    self.create_settings_page()
    ~~~~~~~~~~~~~~~~~~~~~~~~~^^
  File "c:\Users\Utilisateur\Desktop\jeux en python\lancer1.py", line 787, in create_settings_page
    ttk.Button(maintenance_frame, text=text, command=cmd, bootstyle="secondary-round").grid(row=row, column=col, sticky="ew", padx=10, pady=5)
    ~~~~~~~~~~^^^^^^^^^^^^^^^^^^^^^^^^^^^^^^^^^^^^^^^^^^^^^^^^^^^^^^^^^^^^^^^^^^^^^^^^
  File "C:\Users\Utilisateur\AppData\Local\Programs\Python\Python313\Lib\site-packages\ttkbootstrap\style.py", line 5201, in __init__
    ttkstyle = Bootstyle.update_ttk_widget_style(
        self, bootstyle, **kwargs
    )
  File "C:\Users\Utilisateur\AppData\Local\Programs\Python\Python313\Lib\site-packages\ttkbootstrap\style.py", line 5295, in update_ttk_widget_style
    builder_method = builder.name_to_method(method_name)
  File "C:\Users\Utilisateur\AppData\Local\Programs\Python\Python313\Lib\site-packages\ttkbootstrap\style.py", line 1241, in name_to_method
    func = getattr(StyleBuilderTTK, method_name)
AttributeError: type object 'StyleBuilderTTK' has no attribute 'create_round_button_style'. Did you mean: 'create_link_button_style'?
----------------------------------------
Rapport d'erreur - 2025-08-23 15:19:21
Message: L'application a rencontré une erreur fatale et va se fermer.
Erreur: type object 'StyleBuilderTTK' has no attribute 'create_round_button_style'
Traceback:
Traceback (most recent call last):
  File "c:\Users\Utilisateur\Desktop\jeux en python\lancer1.py", line 2084, in <module>
    app = GameLauncher()
  File "c:\Users\Utilisateur\Desktop\jeux en python\lancer1.py", line 323, in __init__
    self.create_settings_page()
    ~~~~~~~~~~~~~~~~~~~~~~~~~^^
  File "c:\Users\Utilisateur\Desktop\jeux en python\lancer1.py", line 787, in create_settings_page
    ttk.Button(maintenance_frame, text=text, command=cmd, bootstyle="secondary,round").grid(row=row, column=col, sticky="ew", padx=10, pady=5)
    ~~~~~~~~~~^^^^^^^^^^^^^^^^^^^^^^^^^^^^^^^^^^^^^^^^^^^^^^^^^^^^^^^^^^^^^^^^^^^^^^^^
  File "C:\Users\Utilisateur\AppData\Local\Programs\Python\Python313\Lib\site-packages\ttkbootstrap\style.py", line 5201, in __init__
    ttkstyle = Bootstyle.update_ttk_widget_style(
        self, bootstyle, **kwargs
    )
  File "C:\Users\Utilisateur\AppData\Local\Programs\Python\Python313\Lib\site-packages\ttkbootstrap\style.py", line 5295, in update_ttk_widget_style
    builder_method = builder.name_to_method(method_name)
  File "C:\Users\Utilisateur\AppData\Local\Programs\Python\Python313\Lib\site-packages\ttkbootstrap\style.py", line 1241, in name_to_method
    func = getattr(StyleBuilderTTK, method_name)
AttributeError: type object 'StyleBuilderTTK' has no attribute 'create_round_button_style'. Did you mean: 'create_link_button_style'?
----------------------------------------
Rapport d'erreur - 2025-08-23 15:19:23
Message: L'application a rencontré une erreur fatale et va se fermer.
Erreur: type object 'StyleBuilderTTK' has no attribute 'create_round_button_style'
Traceback:
Traceback (most recent call last):
  File "c:\Users\Utilisateur\Desktop\jeux en python\lancer1.py", line 2084, in <module>
    app = GameLauncher()
  File "c:\Users\Utilisateur\Desktop\jeux en python\lancer1.py", line 323, in __init__
    self.create_settings_page()
    ~~~~~~~~~~~~~~~~~~~~~~~~~^^
  File "c:\Users\Utilisateur\Desktop\jeux en python\lancer1.py", line 787, in create_settings_page
    ttk.Button(maintenance_frame, text=text, command=cmd, bootstyle="secondary,round").grid(row=row, column=col, sticky="ew", padx=10, pady=5)
    ~~~~~~~~~~^^^^^^^^^^^^^^^^^^^^^^^^^^^^^^^^^^^^^^^^^^^^^^^^^^^^^^^^^^^^^^^^^^^^^^^^
  File "C:\Users\Utilisateur\AppData\Local\Programs\Python\Python313\Lib\site-packages\ttkbootstrap\style.py", line 5201, in __init__
    ttkstyle = Bootstyle.update_ttk_widget_style(
        self, bootstyle, **kwargs
    )
  File "C:\Users\Utilisateur\AppData\Local\Programs\Python\Python313\Lib\site-packages\ttkbootstrap\style.py", line 5295, in update_ttk_widget_style
    builder_method = builder.name_to_method(method_name)
  File "C:\Users\Utilisateur\AppData\Local\Programs\Python\Python313\Lib\site-packages\ttkbootstrap\style.py", line 1241, in name_to_method
    func = getattr(StyleBuilderTTK, method_name)
AttributeError: type object 'StyleBuilderTTK' has no attribute 'create_round_button_style'. Did you mean: 'create_link_button_style'?
----------------------------------------
Rapport d'erreur - 2025-08-23 15:19:37
Message: L'application a rencontré une erreur fatale et va se fermer.
Erreur: type object 'StyleBuilderTTK' has no attribute 'create_round_button_style'
Traceback:
Traceback (most recent call last):
  File "c:\Users\Utilisateur\Desktop\jeux en python\lancer1.py", line 2084, in <module>
    app = GameLauncher()
  File "c:\Users\Utilisateur\Desktop\jeux en python\lancer1.py", line 323, in __init__
    self.create_settings_page()
    ~~~~~~~~~~~~~~~~~~~~~~~~~^^
  File "c:\Users\Utilisateur\Desktop\jeux en python\lancer1.py", line 787, in create_settings_page
    ttk.Button(maintenance_frame, text=text, command=cmd, bootstyle="secondary,round").grid(row=row, column=col, sticky="ew", padx=10, pady=5)
    ~~~~~~~~~~^^^^^^^^^^^^^^^^^^^^^^^^^^^^^^^^^^^^^^^^^^^^^^^^^^^^^^^^^^^^^^^^^^^^^^^^
  File "C:\Users\Utilisateur\AppData\Local\Programs\Python\Python313\Lib\site-packages\ttkbootstrap\style.py", line 5201, in __init__
    ttkstyle = Bootstyle.update_ttk_widget_style(
        self, bootstyle, **kwargs
    )
  File "C:\Users\Utilisateur\AppData\Local\Programs\Python\Python313\Lib\site-packages\ttkbootstrap\style.py", line 5295, in update_ttk_widget_style
    builder_method = builder.name_to_method(method_name)
  File "C:\Users\Utilisateur\AppData\Local\Programs\Python\Python313\Lib\site-packages\ttkbootstrap\style.py", line 1241, in name_to_method
    func = getattr(StyleBuilderTTK, method_name)
AttributeError: type object 'StyleBuilderTTK' has no attribute 'create_round_button_style'. Did you mean: 'create_link_button_style'?
----------------------------------------
Rapport d'erreur - 2025-08-23 15:21:20
Message: L'application a rencontré une erreur fatale et va se fermer.
Erreur: type object 'StyleBuilderTTK' has no attribute 'create_round_button_style'
Traceback:
Traceback (most recent call last):
  File "c:\Users\Utilisateur\Desktop\jeux en python\lancer1.py", line 2084, in <module>
    app = GameLauncher()
  File "c:\Users\Utilisateur\Desktop\jeux en python\lancer1.py", line 323, in __init__
    self.create_settings_page()
    ~~~~~~~~~~~~~~~~~~~~~~~~~^^
  File "c:\Users\Utilisateur\Desktop\jeux en python\lancer1.py", line 787, in create_settings_page
    ttk.Button(maintenance_frame, text=text, command=cmd, bootstyle="secondary,round").grid(row=row, column=col, sticky="ew", padx=10, pady=5)
    ~~~~~~~~~~^^^^^^^^^^^^^^^^^^^^^^^^^^^^^^^^^^^^^^^^^^^^^^^^^^^^^^^^^^^^^^^^^^^^^^^^
  File "C:\Users\Utilisateur\AppData\Local\Programs\Python\Python313\Lib\site-packages\ttkbootstrap\style.py", line 5201, in __init__
    ttkstyle = Bootstyle.update_ttk_widget_style(
        self, bootstyle, **kwargs
    )
  File "C:\Users\Utilisateur\AppData\Local\Programs\Python\Python313\Lib\site-packages\ttkbootstrap\style.py", line 5295, in update_ttk_widget_style
    builder_method = builder.name_to_method(method_name)
  File "C:\Users\Utilisateur\AppData\Local\Programs\Python\Python313\Lib\site-packages\ttkbootstrap\style.py", line 1241, in name_to_method
    func = getattr(StyleBuilderTTK, method_name)
AttributeError: type object 'StyleBuilderTTK' has no attribute 'create_round_button_style'. Did you mean: 'create_link_button_style'?
----------------------------------------
Rapport d'erreur - 2025-08-23 15:22:38
Message: L'application a rencontré une erreur fatale et va se fermer.
Erreur: type object 'StyleBuilderTTK' has no attribute 'create_round_button_style'
Traceback:
Traceback (most recent call last):
  File "c:\Users\Utilisateur\Desktop\jeux en python\lancer1.py", line 2084, in <module>
    app = GameLauncher()
  File "c:\Users\Utilisateur\Desktop\jeux en python\lancer1.py", line 323, in __init__
    self.create_settings_page()
    ~~~~~~~~~~~~~~~~~~~~~~~~~^^
  File "c:\Users\Utilisateur\Desktop\jeux en python\lancer1.py", line 787, in create_settings_page
    ttk.Button(maintenance_frame, text=text, command=cmd, bootstyle="secondary-round").grid(row=row, column=col, sticky="ew", padx=10, pady=5)
    ~~~~~~~~~~^^^^^^^^^^^^^^^^^^^^^^^^^^^^^^^^^^^^^^^^^^^^^^^^^^^^^^^^^^^^^^^^^^^^^^^^
  File "C:\Users\Utilisateur\AppData\Local\Programs\Python\Python313\Lib\site-packages\ttkbootstrap\style.py", line 5201, in __init__
    ttkstyle = Bootstyle.update_ttk_widget_style(
        self, bootstyle, **kwargs
    )
  File "C:\Users\Utilisateur\AppData\Local\Programs\Python\Python313\Lib\site-packages\ttkbootstrap\style.py", line 5295, in update_ttk_widget_style
    builder_method = builder.name_to_method(method_name)
  File "C:\Users\Utilisateur\AppData\Local\Programs\Python\Python313\Lib\site-packages\ttkbootstrap\style.py", line 1241, in name_to_method
    func = getattr(StyleBuilderTTK, method_name)
AttributeError: type object 'StyleBuilderTTK' has no attribute 'create_round_button_style'. Did you mean: 'create_link_button_style'?
----------------------------------------
Rapport d'erreur - 2025-08-23 15:25:22
Message: L'application a rencontré une erreur fatale et va se fermer.
Erreur: type object 'StyleBuilderTTK' has no attribute 'create_round_button_style'
Traceback:
Traceback (most recent call last):
  File "c:\Users\Utilisateur\Desktop\jeux en python\lancer1.py", line 2084, in <module>
    app = GameLauncher()
  File "c:\Users\Utilisateur\Desktop\jeux en python\lancer1.py", line 323, in __init__
    self.create_settings_page()
    ~~~~~~~~~~~~~~~~~~~~~~~~~^^
  File "c:\Users\Utilisateur\Desktop\jeux en python\lancer1.py", line 787, in create_settings_page
    ttk.Button(maintenance_frame, text=text, command=cmd, bootstyle="secondary,round").grid(row=row, column=col, sticky="ew", padx=10, pady=5)
    ~~~~~~~~~~^^^^^^^^^^^^^^^^^^^^^^^^^^^^^^^^^^^^^^^^^^^^^^^^^^^^^^^^^^^^^^^^^^^^^^^^
  File "C:\Users\Utilisateur\AppData\Local\Programs\Python\Python313\Lib\site-packages\ttkbootstrap\style.py", line 5201, in __init__
    ttkstyle = Bootstyle.update_ttk_widget_style(
        self, bootstyle, **kwargs
    )
  File "C:\Users\Utilisateur\AppData\Local\Programs\Python\Python313\Lib\site-packages\ttkbootstrap\style.py", line 5295, in update_ttk_widget_style
    builder_method = builder.name_to_method(method_name)
  File "C:\Users\Utilisateur\AppData\Local\Programs\Python\Python313\Lib\site-packages\ttkbootstrap\style.py", line 1241, in name_to_method
    func = getattr(StyleBuilderTTK, method_name)
AttributeError: type object 'StyleBuilderTTK' has no attribute 'create_round_button_style'. Did you mean: 'create_link_button_style'?
----------------------------------------
Rapport d'erreur - 2025-08-23 15:50:57
Message: L'application a rencontré une erreur fatale et va se fermer.
Erreur: '_tkinter.tkapp' object has no attribute 'load_achievements'
Traceback:
Traceback (most recent call last):
  File "c:\Users\Utilisateur\Desktop\jeux en python\lancer1.py", line 2080, in <module>
    app = GameLauncher()
  File "c:\Users\Utilisateur\Desktop\jeux en python\lancer1.py", line 195, in __init__
    self.achievements_data = self.load_achievements()
                             ^^^^^^^^^^^^^^^^^^^^^^
  File "C:\Users\Utilisateur\AppData\Local\Programs\Python\Python313\Lib\tkinter\__init__.py", line 2552, in __getattr__
    return getattr(self.tk, attr)
AttributeError: '_tkinter.tkapp' object has no attribute 'load_achievements'
----------------------------------------
Rapport d'erreur - 2025-08-23 16:05:45
Message: L'application a rencontré une erreur fatale et va se fermer.
Erreur: '_tkinter.tkapp' object has no attribute 'main_page_frame'
Traceback:
Traceback (most recent call last):
  File "c:\Users\Utilisateur\Desktop\jeux en python\lancer1.py", line 2358, in <module>
    app = GameLauncher()
  File "c:\Users\Utilisateur\Desktop\jeux en python\lancer1.py", line 188, in __init__
    "main": self.main_page_frame, "games": self.games_page_frame,
            ^^^^^^^^^^^^^^^^^^^^
  File "C:\Users\Utilisateur\AppData\Local\Programs\Python\Python313\Lib\tkinter\__init__.py", line 2552, in __getattr__
    return getattr(self.tk, attr)
AttributeError: '_tkinter.tkapp' object has no attribute 'main_page_frame'
----------------------------------------
Rapport d'erreur - 2025-08-23 16:14:44
Message: L'application a rencontré une erreur fatale et va se fermer.
Erreur: '_tkinter.tkapp' object has no attribute '_on_global_mouse_wheel'
Traceback:
Traceback (most recent call last):
  File "c:\Users\Utilisateur\Desktop\jeux en python\lancer1.py", line 2338, in <module>
    app = GameLauncher()
  File "c:\Users\Utilisateur\Desktop\jeux en python\lancer1.py", line 280, in __init__
    self.bind_all("<MouseWheel>", self._on_global_mouse_wheel)
                                  ^^^^^^^^^^^^^^^^^^^^^^^^^^^
  File "C:\Users\Utilisateur\AppData\Local\Programs\Python\Python313\Lib\tkinter\__init__.py", line 2552, in __getattr__
    return getattr(self.tk, attr)
AttributeError: '_tkinter.tkapp' object has no attribute '_on_global_mouse_wheel'
----------------------------------------
Rapport d'erreur - 2025-08-23 17:30:55
Message: Fichier de données principal 'collections.json' corrompu ou absent.
----------------------------------------
Rapport d'erreur - 2025-08-23 17:31:06
Message: Failed to check for updates
Erreur: HTTP Error 404: Not Found
Traceback:
Traceback (most recent call last):
  File "c:\Users\Utilisateur\Desktop\jeux en python\lancer1.py", line 2412, in _check_for_updates_worker
    with urllib.request.urlopen(UPDATE_URL, timeout=10) as response:
         ~~~~~~~~~~~~~~~~~~~~~~^^^^^^^^^^^^^^^^^^^^^^^^
  File "C:\Users\Utilisateur\AppData\Local\Programs\Python\Python313\Lib\urllib\request.py", line 189, in urlopen
    return opener.open(url, data, timeout)
           ~~~~~~~~~~~^^^^^^^^^^^^^^^^^^^^
  File "C:\Users\Utilisateur\AppData\Local\Programs\Python\Python313\Lib\urllib\request.py", line 495, in open
    response = meth(req, response)
  File "C:\Users\Utilisateur\AppData\Local\Programs\Python\Python313\Lib\urllib\request.py", line 604, in http_response
    response = self.parent.error(
        'http', request, response, code, msg, hdrs)
  File "C:\Users\Utilisateur\AppData\Local\Programs\Python\Python313\Lib\urllib\request.py", line 533, in error
    return self._call_chain(*args)
           ~~~~~~~~~~~~~~~~^^^^^^^
  File "C:\Users\Utilisateur\AppData\Local\Programs\Python\Python313\Lib\urllib\request.py", line 466, in _call_chain
    result = func(*args)
  File "C:\Users\Utilisateur\AppData\Local\Programs\Python\Python313\Lib\urllib\request.py", line 613, in http_error_default
    raise HTTPError(req.full_url, code, msg, hdrs, fp)
urllib.error.HTTPError: HTTP Error 404: Not Found
----------------------------------------
Rapport d'erreur - 2025-08-23 17:34:05
Message: Fichier de données principal 'collections.json' corrompu ou absent.
----------------------------------------
Rapport d'erreur - 2025-08-23 17:34:17
Message: Failed to check for updates
Erreur: HTTP Error 404: Not Found
Traceback:
Traceback (most recent call last):
  File "c:\Users\Utilisateur\Desktop\jeux en python\lancer1.py", line 2415, in _check_for_updates_worker
    with urllib.request.urlopen(UPDATE_URL, timeout=10) as response:
         ~~~~~~~~~~~~~~~~~~~~~~^^^^^^^^^^^^^^^^^^^^^^^^
  File "C:\Users\Utilisateur\AppData\Local\Programs\Python\Python313\Lib\urllib\request.py", line 189, in urlopen
    return opener.open(url, data, timeout)
           ~~~~~~~~~~~^^^^^^^^^^^^^^^^^^^^
  File "C:\Users\Utilisateur\AppData\Local\Programs\Python\Python313\Lib\urllib\request.py", line 495, in open
    response = meth(req, response)
  File "C:\Users\Utilisateur\AppData\Local\Programs\Python\Python313\Lib\urllib\request.py", line 604, in http_response
    response = self.parent.error(
        'http', request, response, code, msg, hdrs)
  File "C:\Users\Utilisateur\AppData\Local\Programs\Python\Python313\Lib\urllib\request.py", line 533, in error
    return self._call_chain(*args)
           ~~~~~~~~~~~~~~~~^^^^^^^
  File "C:\Users\Utilisateur\AppData\Local\Programs\Python\Python313\Lib\urllib\request.py", line 466, in _call_chain
    result = func(*args)
  File "C:\Users\Utilisateur\AppData\Local\Programs\Python\Python313\Lib\urllib\request.py", line 613, in http_error_default
    raise HTTPError(req.full_url, code, msg, hdrs, fp)
urllib.error.HTTPError: HTTP Error 404: Not Found
----------------------------------------
Rapport d'erreur - 2025-08-23 17:35:34
Message: Fichier de données principal 'collections.json' corrompu ou absent.
----------------------------------------
Rapport d'erreur - 2025-08-23 17:35:42
Message: Failed to check for updates
Erreur: HTTP Error 404: Not Found
Traceback:
Traceback (most recent call last):
  File "c:\Users\Utilisateur\Desktop\jeux en python\lancer1.py", line 2415, in _check_for_updates_worker
    with urllib.request.urlopen(UPDATE_URL, timeout=10) as response:
         ~~~~~~~~~~~~~~~~~~~~~~^^^^^^^^^^^^^^^^^^^^^^^^
  File "C:\Users\Utilisateur\AppData\Local\Programs\Python\Python313\Lib\urllib\request.py", line 189, in urlopen
    return opener.open(url, data, timeout)
           ~~~~~~~~~~~^^^^^^^^^^^^^^^^^^^^
  File "C:\Users\Utilisateur\AppData\Local\Programs\Python\Python313\Lib\urllib\request.py", line 495, in open
    response = meth(req, response)
  File "C:\Users\Utilisateur\AppData\Local\Programs\Python\Python313\Lib\urllib\request.py", line 604, in http_response
    response = self.parent.error(
        'http', request, response, code, msg, hdrs)
  File "C:\Users\Utilisateur\AppData\Local\Programs\Python\Python313\Lib\urllib\request.py", line 533, in error
    return self._call_chain(*args)
           ~~~~~~~~~~~~~~~~^^^^^^^
  File "C:\Users\Utilisateur\AppData\Local\Programs\Python\Python313\Lib\urllib\request.py", line 466, in _call_chain
    result = func(*args)
  File "C:\Users\Utilisateur\AppData\Local\Programs\Python\Python313\Lib\urllib\request.py", line 613, in http_error_default
    raise HTTPError(req.full_url, code, msg, hdrs, fp)
urllib.error.HTTPError: HTTP Error 404: Not Found
----------------------------------------
Rapport d'erreur - 2025-08-23 17:36:02
Message: Failed to check for updates
Erreur: HTTP Error 404: Not Found
Traceback:
Traceback (most recent call last):
  File "c:\Users\Utilisateur\Desktop\jeux en python\lancer1.py", line 2415, in _check_for_updates_worker
    with urllib.request.urlopen(UPDATE_URL, timeout=10) as response:
         ~~~~~~~~~~~~~~~~~~~~~~^^^^^^^^^^^^^^^^^^^^^^^^
  File "C:\Users\Utilisateur\AppData\Local\Programs\Python\Python313\Lib\urllib\request.py", line 189, in urlopen
    return opener.open(url, data, timeout)
           ~~~~~~~~~~~^^^^^^^^^^^^^^^^^^^^
  File "C:\Users\Utilisateur\AppData\Local\Programs\Python\Python313\Lib\urllib\request.py", line 495, in open
    response = meth(req, response)
  File "C:\Users\Utilisateur\AppData\Local\Programs\Python\Python313\Lib\urllib\request.py", line 604, in http_response
    response = self.parent.error(
        'http', request, response, code, msg, hdrs)
  File "C:\Users\Utilisateur\AppData\Local\Programs\Python\Python313\Lib\urllib\request.py", line 533, in error
    return self._call_chain(*args)
           ~~~~~~~~~~~~~~~~^^^^^^^
  File "C:\Users\Utilisateur\AppData\Local\Programs\Python\Python313\Lib\urllib\request.py", line 466, in _call_chain
    result = func(*args)
  File "C:\Users\Utilisateur\AppData\Local\Programs\Python\Python313\Lib\urllib\request.py", line 613, in http_error_default
    raise HTTPError(req.full_url, code, msg, hdrs, fp)
urllib.error.HTTPError: HTTP Error 404: Not Found
----------------------------------------
Rapport d'erreur - 2025-08-23 17:38:53
Message: Fichier de données principal 'collections.json' corrompu ou absent.
----------------------------------------
Rapport d'erreur - 2025-08-23 17:41:05
Message: Fichier de données principal 'collections.json' corrompu ou absent. Tentative de restauration...
----------------------------------------
Rapport d'erreur - 2025-08-23 17:41:05
Message: Création d'un nouveau fichier de données pour 'collections.json'.
----------------------------------------
Rapport d'erreur - 2025-08-23 17:41:11
Message: Failed to check for updates
Erreur: HTTP Error 404: Not Found
Traceback:
Traceback (most recent call last):
  File "c:\Users\Utilisateur\Desktop\jeux en python\lancer1.py", line 2417, in _check_for_updates_worker
    with urllib.request.urlopen(UPDATE_URL, timeout=10) as response:
         ~~~~~~~~~~~~~~~~~~~~~~^^^^^^^^^^^^^^^^^^^^^^^^
  File "C:\Users\Utilisateur\AppData\Local\Programs\Python\Python313\Lib\urllib\request.py", line 189, in urlopen
    return opener.open(url, data, timeout)
           ~~~~~~~~~~~^^^^^^^^^^^^^^^^^^^^
  File "C:\Users\Utilisateur\AppData\Local\Programs\Python\Python313\Lib\urllib\request.py", line 495, in open
    response = meth(req, response)
  File "C:\Users\Utilisateur\AppData\Local\Programs\Python\Python313\Lib\urllib\request.py", line 604, in http_response
    response = self.parent.error(
        'http', request, response, code, msg, hdrs)
  File "C:\Users\Utilisateur\AppData\Local\Programs\Python\Python313\Lib\urllib\request.py", line 533, in error
    return self._call_chain(*args)
           ~~~~~~~~~~~~~~~~^^^^^^^
  File "C:\Users\Utilisateur\AppData\Local\Programs\Python\Python313\Lib\urllib\request.py", line 466, in _call_chain
    result = func(*args)
  File "C:\Users\Utilisateur\AppData\Local\Programs\Python\Python313\Lib\urllib\request.py", line 613, in http_error_default
    raise HTTPError(req.full_url, code, msg, hdrs, fp)
urllib.error.HTTPError: HTTP Error 404: Not Found
----------------------------------------
Rapport d'erreur - 2025-08-23 17:45:27
Message: Failed to check for updates
Erreur: HTTP Error 404: Not Found
Traceback:
Traceback (most recent call last):
  File "c:\Users\Utilisateur\Desktop\jeux en python\lancer1.py", line 2418, in _check_for_updates_worker
    with urllib.request.urlopen(UPDATE_URL, timeout=10) as response:
         ~~~~~~~~~~~~~~~~~~~~~~^^^^^^^^^^^^^^^^^^^^^^^^
  File "C:\Users\Utilisateur\AppData\Local\Programs\Python\Python313\Lib\urllib\request.py", line 189, in urlopen
    return opener.open(url, data, timeout)
           ~~~~~~~~~~~^^^^^^^^^^^^^^^^^^^^
  File "C:\Users\Utilisateur\AppData\Local\Programs\Python\Python313\Lib\urllib\request.py", line 495, in open
    response = meth(req, response)
  File "C:\Users\Utilisateur\AppData\Local\Programs\Python\Python313\Lib\urllib\request.py", line 604, in http_response
    response = self.parent.error(
        'http', request, response, code, msg, hdrs)
  File "C:\Users\Utilisateur\AppData\Local\Programs\Python\Python313\Lib\urllib\request.py", line 533, in error
    return self._call_chain(*args)
           ~~~~~~~~~~~~~~~~^^^^^^^
  File "C:\Users\Utilisateur\AppData\Local\Programs\Python\Python313\Lib\urllib\request.py", line 466, in _call_chain
    result = func(*args)
  File "C:\Users\Utilisateur\AppData\Local\Programs\Python\Python313\Lib\urllib\request.py", line 613, in http_error_default
    raise HTTPError(req.full_url, code, msg, hdrs, fp)
urllib.error.HTTPError: HTTP Error 404: Not Found
----------------------------------------
Rapport d'erreur - 2025-08-23 17:48:36
Message: Failed to check for updates
Erreur: HTTP Error 404: Not Found
Traceback:
Traceback (most recent call last):
  File "c:\Users\Utilisateur\Desktop\jeux en python\lancer1.py", line 2418, in _check_for_updates_worker
    with urllib.request.urlopen(UPDATE_URL, timeout=10) as response:
         ~~~~~~~~~~~~~~~~~~~~~~^^^^^^^^^^^^^^^^^^^^^^^^
  File "C:\Users\Utilisateur\AppData\Local\Programs\Python\Python313\Lib\urllib\request.py", line 189, in urlopen
    return opener.open(url, data, timeout)
           ~~~~~~~~~~~^^^^^^^^^^^^^^^^^^^^
  File "C:\Users\Utilisateur\AppData\Local\Programs\Python\Python313\Lib\urllib\request.py", line 495, in open
    response = meth(req, response)
  File "C:\Users\Utilisateur\AppData\Local\Programs\Python\Python313\Lib\urllib\request.py", line 604, in http_response
    response = self.parent.error(
        'http', request, response, code, msg, hdrs)
  File "C:\Users\Utilisateur\AppData\Local\Programs\Python\Python313\Lib\urllib\request.py", line 533, in error
    return self._call_chain(*args)
           ~~~~~~~~~~~~~~~~^^^^^^^
  File "C:\Users\Utilisateur\AppData\Local\Programs\Python\Python313\Lib\urllib\request.py", line 466, in _call_chain
    result = func(*args)
  File "C:\Users\Utilisateur\AppData\Local\Programs\Python\Python313\Lib\urllib\request.py", line 613, in http_error_default
    raise HTTPError(req.full_url, code, msg, hdrs, fp)
urllib.error.HTTPError: HTTP Error 404: Not Found
----------------------------------------
Rapport d'erreur - 2025-08-23 17:50:56
Message: Failed to check for updates
Erreur: HTTP Error 404: Not Found
Traceback:
Traceback (most recent call last):
  File "c:\Users\Utilisateur\Desktop\jeux en python\lancer1.py", line 2424, in _check_for_updates_worker
    with urllib.request.urlopen(UPDATE_URL, timeout=10) as response:
         ~~~~~~~~~~~~~~~~~~~~~~^^^^^^^^^^^^^^^^^^^^^^^^
  File "C:\Users\Utilisateur\AppData\Local\Programs\Python\Python313\Lib\urllib\request.py", line 189, in urlopen
    return opener.open(url, data, timeout)
           ~~~~~~~~~~~^^^^^^^^^^^^^^^^^^^^
  File "C:\Users\Utilisateur\AppData\Local\Programs\Python\Python313\Lib\urllib\request.py", line 495, in open
    response = meth(req, response)
  File "C:\Users\Utilisateur\AppData\Local\Programs\Python\Python313\Lib\urllib\request.py", line 604, in http_response
    response = self.parent.error(
        'http', request, response, code, msg, hdrs)
  File "C:\Users\Utilisateur\AppData\Local\Programs\Python\Python313\Lib\urllib\request.py", line 533, in error
    return self._call_chain(*args)
           ~~~~~~~~~~~~~~~~^^^^^^^
  File "C:\Users\Utilisateur\AppData\Local\Programs\Python\Python313\Lib\urllib\request.py", line 466, in _call_chain
    result = func(*args)
  File "C:\Users\Utilisateur\AppData\Local\Programs\Python\Python313\Lib\urllib\request.py", line 613, in http_error_default
    raise HTTPError(req.full_url, code, msg, hdrs, fp)
urllib.error.HTTPError: HTTP Error 404: Not Found
----------------------------------------
Rapport d'erreur - 2025-08-23 17:52:59
Message: L'application a rencontré une erreur fatale et va se fermer.
Erreur: unknown option "-bootstyle"
Traceback:
Traceback (most recent call last):
  File "c:\Users\Utilisateur\Desktop\jeux en python\lancer1.py", line 2969, in <module>
    app = GameLauncher()
  File "c:\Users\Utilisateur\Desktop\jeux en python\lancer1.py", line 268, in __init__
    self.create_main_page()
    ~~~~~~~~~~~~~~~~~~~~~^^
  File "c:\Users\Utilisateur\Desktop\jeux en python\lancer1.py", line 880, in create_main_page
    self.total_games_label, card_games = self.create_dashboard_card(dashboard_frame, "Jeux", "0", 0, 0)
                                         ~~~~~~~~~~~~~~~~~~~~~~~~~~^^^^^^^^^^^^^^^^^^^^^^^^^^^^^^^^^^^^
  File "c:\Users\Utilisateur\Desktop\jeux en python\lancer1.py", line 950, in create_dashboard_card
    child.configure(style=f"inverse-{card.cget('bootstyle')}.TLabel")
                                     ~~~~~~~~~^^^^^^^^^^^^^
  File "C:\Users\Utilisateur\AppData\Local\Programs\Python\Python313\Lib\tkinter\__init__.py", line 1834, in cget
    return self.tk.call(self._w, 'cget', '-' + key)
           ~~~~~~~~~~~~^^^^^^^^^^^^^^^^^^^^^^^^^^^^
_tkinter.TclError: unknown option "-bootstyle"
----------------------------------------
Rapport d'erreur - 2025-08-23 17:56:12
Message: L'application a rencontré une erreur fatale et va se fermer.
Erreur: unknown option "-bootstyle"
Traceback:
Traceback (most recent call last):
  File "c:\Users\Utilisateur\Desktop\jeux en python\lancer1.py", line 2969, in <module>
    app = GameLauncher()
  File "c:\Users\Utilisateur\Desktop\jeux en python\lancer1.py", line 268, in __init__
    self.create_main_page()
    ~~~~~~~~~~~~~~~~~~~~~^^
  File "c:\Users\Utilisateur\Desktop\jeux en python\lancer1.py", line 880, in create_main_page
    self.total_games_label, card_games = self.create_dashboard_card(dashboard_frame, "Jeux", "0", 0, 0)
                                         ~~~~~~~~~~~~~~~~~~~~~~~~~~^^^^^^^^^^^^^^^^^^^^^^^^^^^^^^^^^^^^
  File "c:\Users\Utilisateur\Desktop\jeux en python\lancer1.py", line 950, in create_dashboard_card
    child.configure(style=f"inverse-{card.cget('bootstyle')}.TLabel")
                                     ~~~~~~~~~^^^^^^^^^^^^^
  File "C:\Users\Utilisateur\AppData\Local\Programs\Python\Python313\Lib\tkinter\__init__.py", line 1834, in cget
    return self.tk.call(self._w, 'cget', '-' + key)
           ~~~~~~~~~~~~^^^^^^^^^^^^^^^^^^^^^^^^^^^^
_tkinter.TclError: unknown option "-bootstyle"
----------------------------------------
Rapport d'erreur - 2025-08-23 17:57:32
Message: L'application a rencontré une erreur fatale et va se fermer.
Erreur: type object 'StyleBuilderTTK' has no attribute 'create_link_label_style'
Traceback:
Traceback (most recent call last):
  File "c:\Users\Utilisateur\Desktop\jeux en python\lancer1.py", line 2969, in <module>
    app = GameLauncher()
  File "c:\Users\Utilisateur\Desktop\jeux en python\lancer1.py", line 272, in __init__
    self.create_pro_page()
    ~~~~~~~~~~~~~~~~~~~~^^
  File "c:\Users\Utilisateur\Desktop\jeux en python\lancer1.py", line 1326, in create_pro_page
    link = ttk.Label(about_container, text="Développé avec Python et Tkinter. Voir sur GitHub.", bootstyle="secondary,link")
           ~~~~~~~~~^^^^^^^^^^^^^^^^^^^^^^^^^^^^^^^^^^^^^^^^^^^^^^^^^^^^^^^^^^^^^^^^^^^^^^^^^^^^^^^^^^^^^^^^^^^^^^^^^^^^^^^^
  File "C:\Users\Utilisateur\AppData\Local\Programs\Python\Python313\Lib\site-packages\ttkbootstrap\style.py", line 5201, in __init__
    ttkstyle = Bootstyle.update_ttk_widget_style(
        self, bootstyle, **kwargs
    )
  File "C:\Users\Utilisateur\AppData\Local\Programs\Python\Python313\Lib\site-packages\ttkbootstrap\style.py", line 5295, in update_ttk_widget_style
    builder_method = builder.name_to_method(method_name)
  File "C:\Users\Utilisateur\AppData\Local\Programs\Python\Python313\Lib\site-packages\ttkbootstrap\style.py", line 1241, in name_to_method
    func = getattr(StyleBuilderTTK, method_name)
AttributeError: type object 'StyleBuilderTTK' has no attribute 'create_link_label_style'. Did you mean: 'create_label_style'?
----------------------------------------
Rapport d'erreur - 2025-08-23 17:59:11
Message: Failed to check for updates
Erreur: HTTP Error 404: Not Found
Traceback:
Traceback (most recent call last):
  File "c:\Users\Utilisateur\Desktop\jeux en python\lancer1.py", line 2487, in _check_for_updates_worker
    with urllib.request.urlopen(UPDATE_URL, timeout=10) as response:
         ~~~~~~~~~~~~~~~~~~~~~~^^^^^^^^^^^^^^^^^^^^^^^^
  File "C:\Users\Utilisateur\AppData\Local\Programs\Python\Python313\Lib\urllib\request.py", line 189, in urlopen
    return opener.open(url, data, timeout)
           ~~~~~~~~~~~^^^^^^^^^^^^^^^^^^^^
  File "C:\Users\Utilisateur\AppData\Local\Programs\Python\Python313\Lib\urllib\request.py", line 495, in open
    response = meth(req, response)
  File "C:\Users\Utilisateur\AppData\Local\Programs\Python\Python313\Lib\urllib\request.py", line 604, in http_response
    response = self.parent.error(
        'http', request, response, code, msg, hdrs)
  File "C:\Users\Utilisateur\AppData\Local\Programs\Python\Python313\Lib\urllib\request.py", line 533, in error
    return self._call_chain(*args)
           ~~~~~~~~~~~~~~~~^^^^^^^
  File "C:\Users\Utilisateur\AppData\Local\Programs\Python\Python313\Lib\urllib\request.py", line 466, in _call_chain
    result = func(*args)
  File "C:\Users\Utilisateur\AppData\Local\Programs\Python\Python313\Lib\urllib\request.py", line 613, in http_error_default
    raise HTTPError(req.full_url, code, msg, hdrs, fp)
urllib.error.HTTPError: HTTP Error 404: Not Found
----------------------------------------
Rapport d'erreur - 2025-08-23 18:11:21
Message: Failed to check for updates
Erreur: HTTP Error 404: Not Found
Traceback:
Traceback (most recent call last):
  File "c:\Users\Utilisateur\Desktop\jeux en python\lancer1.py", line 2487, in _check_for_updates_worker
    with urllib.request.urlopen(UPDATE_URL, timeout=10) as response:
         ~~~~~~~~~~~~~~~~~~~~~~^^^^^^^^^^^^^^^^^^^^^^^^
  File "C:\Users\Utilisateur\AppData\Local\Programs\Python\Python313\Lib\urllib\request.py", line 189, in urlopen
    return opener.open(url, data, timeout)
           ~~~~~~~~~~~^^^^^^^^^^^^^^^^^^^^
  File "C:\Users\Utilisateur\AppData\Local\Programs\Python\Python313\Lib\urllib\request.py", line 495, in open
    response = meth(req, response)
  File "C:\Users\Utilisateur\AppData\Local\Programs\Python\Python313\Lib\urllib\request.py", line 604, in http_response
    response = self.parent.error(
        'http', request, response, code, msg, hdrs)
  File "C:\Users\Utilisateur\AppData\Local\Programs\Python\Python313\Lib\urllib\request.py", line 533, in error
    return self._call_chain(*args)
           ~~~~~~~~~~~~~~~~^^^^^^^
  File "C:\Users\Utilisateur\AppData\Local\Programs\Python\Python313\Lib\urllib\request.py", line 466, in _call_chain
    result = func(*args)
  File "C:\Users\Utilisateur\AppData\Local\Programs\Python\Python313\Lib\urllib\request.py", line 613, in http_error_default
    raise HTTPError(req.full_url, code, msg, hdrs, fp)
urllib.error.HTTPError: HTTP Error 404: Not Found
----------------------------------------
Rapport d'erreur - 2025-08-23 18:28:29
Message: Failed to check for updates
Erreur: HTTP Error 404: Not Found
Traceback:
Traceback (most recent call last):
  File "c:\Users\Utilisateur\Desktop\jeux en python\lancer1.py", line 2608, in _check_for_updates_worker
    with urllib.request.urlopen(UPDATE_URL, timeout=10) as response:
         ~~~~~~~~~~~~~~~~~~~~~~^^^^^^^^^^^^^^^^^^^^^^^^
  File "C:\Users\Utilisateur\AppData\Local\Programs\Python\Python313\Lib\urllib\request.py", line 189, in urlopen
    return opener.open(url, data, timeout)
           ~~~~~~~~~~~^^^^^^^^^^^^^^^^^^^^
  File "C:\Users\Utilisateur\AppData\Local\Programs\Python\Python313\Lib\urllib\request.py", line 495, in open
    response = meth(req, response)
  File "C:\Users\Utilisateur\AppData\Local\Programs\Python\Python313\Lib\urllib\request.py", line 604, in http_response
    response = self.parent.error(
        'http', request, response, code, msg, hdrs)
  File "C:\Users\Utilisateur\AppData\Local\Programs\Python\Python313\Lib\urllib\request.py", line 533, in error
    return self._call_chain(*args)
           ~~~~~~~~~~~~~~~~^^^^^^^
  File "C:\Users\Utilisateur\AppData\Local\Programs\Python\Python313\Lib\urllib\request.py", line 466, in _call_chain
    result = func(*args)
  File "C:\Users\Utilisateur\AppData\Local\Programs\Python\Python313\Lib\urllib\request.py", line 613, in http_error_default
    raise HTTPError(req.full_url, code, msg, hdrs, fp)
urllib.error.HTTPError: HTTP Error 404: Not Found
----------------------------------------
Rapport d'erreur - 2025-08-23 18:29:00
Message: Failed to check for updates
Erreur: HTTP Error 404: Not Found
Traceback:
Traceback (most recent call last):
  File "c:\Users\Utilisateur\Desktop\jeux en python\lancer1.py", line 2608, in _check_for_updates_worker
    with urllib.request.urlopen(UPDATE_URL, timeout=10) as response:
         ~~~~~~~~~~~~~~~~~~~~~~^^^^^^^^^^^^^^^^^^^^^^^^
  File "C:\Users\Utilisateur\AppData\Local\Programs\Python\Python313\Lib\urllib\request.py", line 189, in urlopen
    return opener.open(url, data, timeout)
           ~~~~~~~~~~~^^^^^^^^^^^^^^^^^^^^
  File "C:\Users\Utilisateur\AppData\Local\Programs\Python\Python313\Lib\urllib\request.py", line 495, in open
    response = meth(req, response)
  File "C:\Users\Utilisateur\AppData\Local\Programs\Python\Python313\Lib\urllib\request.py", line 604, in http_response
    response = self.parent.error(
        'http', request, response, code, msg, hdrs)
  File "C:\Users\Utilisateur\AppData\Local\Programs\Python\Python313\Lib\urllib\request.py", line 533, in error
    return self._call_chain(*args)
           ~~~~~~~~~~~~~~~~^^^^^^^
  File "C:\Users\Utilisateur\AppData\Local\Programs\Python\Python313\Lib\urllib\request.py", line 466, in _call_chain
    result = func(*args)
  File "C:\Users\Utilisateur\AppData\Local\Programs\Python\Python313\Lib\urllib\request.py", line 613, in http_error_default
    raise HTTPError(req.full_url, code, msg, hdrs, fp)
urllib.error.HTTPError: HTTP Error 404: Not Found
----------------------------------------
Rapport d'erreur - 2025-08-23 18:32:20
Message: Failed to check for updates
Erreur: HTTP Error 404: Not Found
Traceback:
Traceback (most recent call last):
  File "c:\Users\Utilisateur\Desktop\jeux en python\lancer1.py", line 2632, in _check_for_updates_worker
    with urllib.request.urlopen(UPDATE_URL, timeout=10) as response:
         ~~~~~~~~~~~~~~~~~~~~~~^^^^^^^^^^^^^^^^^^^^^^^^
  File "C:\Users\Utilisateur\AppData\Local\Programs\Python\Python313\Lib\urllib\request.py", line 189, in urlopen
    return opener.open(url, data, timeout)
           ~~~~~~~~~~~^^^^^^^^^^^^^^^^^^^^
  File "C:\Users\Utilisateur\AppData\Local\Programs\Python\Python313\Lib\urllib\request.py", line 495, in open
    response = meth(req, response)
  File "C:\Users\Utilisateur\AppData\Local\Programs\Python\Python313\Lib\urllib\request.py", line 604, in http_response
    response = self.parent.error(
        'http', request, response, code, msg, hdrs)
  File "C:\Users\Utilisateur\AppData\Local\Programs\Python\Python313\Lib\urllib\request.py", line 533, in error
    return self._call_chain(*args)
           ~~~~~~~~~~~~~~~~^^^^^^^
  File "C:\Users\Utilisateur\AppData\Local\Programs\Python\Python313\Lib\urllib\request.py", line 466, in _call_chain
    result = func(*args)
  File "C:\Users\Utilisateur\AppData\Local\Programs\Python\Python313\Lib\urllib\request.py", line 613, in http_error_default
    raise HTTPError(req.full_url, code, msg, hdrs, fp)
urllib.error.HTTPError: HTTP Error 404: Not Found
----------------------------------------
Rapport d'erreur - 2025-08-23 18:33:29
Message: Failed to check for updates
Erreur: HTTP Error 404: Not Found
Traceback:
Traceback (most recent call last):
  File "c:\Users\Utilisateur\Desktop\jeux en python\lancer1.py", line 2666, in _check_for_updates_worker
    with urllib.request.urlopen(UPDATE_URL, timeout=10) as response:
         ~~~~~~~~~~~~~~~~~~~~~~^^^^^^^^^^^^^^^^^^^^^^^^
  File "C:\Users\Utilisateur\AppData\Local\Programs\Python\Python313\Lib\urllib\request.py", line 189, in urlopen
    return opener.open(url, data, timeout)
           ~~~~~~~~~~~^^^^^^^^^^^^^^^^^^^^
  File "C:\Users\Utilisateur\AppData\Local\Programs\Python\Python313\Lib\urllib\request.py", line 495, in open
    response = meth(req, response)
  File "C:\Users\Utilisateur\AppData\Local\Programs\Python\Python313\Lib\urllib\request.py", line 604, in http_response
    response = self.parent.error(
        'http', request, response, code, msg, hdrs)
  File "C:\Users\Utilisateur\AppData\Local\Programs\Python\Python313\Lib\urllib\request.py", line 533, in error
    return self._call_chain(*args)
           ~~~~~~~~~~~~~~~~^^^^^^^
  File "C:\Users\Utilisateur\AppData\Local\Programs\Python\Python313\Lib\urllib\request.py", line 466, in _call_chain
    result = func(*args)
  File "C:\Users\Utilisateur\AppData\Local\Programs\Python\Python313\Lib\urllib\request.py", line 613, in http_error_default
    raise HTTPError(req.full_url, code, msg, hdrs, fp)
urllib.error.HTTPError: HTTP Error 404: Not Found
----------------------------------------
Rapport d'erreur - 2025-08-23 18:36:59
Message: Failed to check for updates
Erreur: HTTP Error 404: Not Found
Traceback:
Traceback (most recent call last):
  File "c:\Users\Utilisateur\Desktop\jeux en python\lancer1.py", line 2690, in _check_for_updates_worker
    with urllib.request.urlopen(UPDATE_URL, timeout=10) as response:
         ~~~~~~~~~~~~~~~~~~~~~~^^^^^^^^^^^^^^^^^^^^^^^^
  File "C:\Users\Utilisateur\AppData\Local\Programs\Python\Python313\Lib\urllib\request.py", line 189, in urlopen
    return opener.open(url, data, timeout)
           ~~~~~~~~~~~^^^^^^^^^^^^^^^^^^^^
  File "C:\Users\Utilisateur\AppData\Local\Programs\Python\Python313\Lib\urllib\request.py", line 495, in open
    response = meth(req, response)
  File "C:\Users\Utilisateur\AppData\Local\Programs\Python\Python313\Lib\urllib\request.py", line 604, in http_response
    response = self.parent.error(
        'http', request, response, code, msg, hdrs)
  File "C:\Users\Utilisateur\AppData\Local\Programs\Python\Python313\Lib\urllib\request.py", line 533, in error
    return self._call_chain(*args)
           ~~~~~~~~~~~~~~~~^^^^^^^
  File "C:\Users\Utilisateur\AppData\Local\Programs\Python\Python313\Lib\urllib\request.py", line 466, in _call_chain
    result = func(*args)
  File "C:\Users\Utilisateur\AppData\Local\Programs\Python\Python313\Lib\urllib\request.py", line 613, in http_error_default
    raise HTTPError(req.full_url, code, msg, hdrs, fp)
urllib.error.HTTPError: HTTP Error 404: Not Found
----------------------------------------
Rapport d'erreur - 2025-08-23 18:39:55
Message: L'application a rencontré une erreur fatale et va se fermer.
Erreur: cannot use geometry manager grid inside .!frame3.!frame5.!notebook.!frame4 which already has slaves managed by pack
Traceback:
Traceback (most recent call last):
  File "c:\Users\Utilisateur\Desktop\jeux en python\lancer1.py", line 3301, in <module>
    app = GameLauncher()
  File "c:\Users\Utilisateur\Desktop\jeux en python\lancer1.py", line 375, in __init__
    self.create_pro_page()
    ~~~~~~~~~~~~~~~~~~~~^^
  File "c:\Users\Utilisateur\Desktop\jeux en python\lancer1.py", line 1553, in create_pro_page
    self.pro_suggestion_frame.grid(row=1, column=0, sticky="nsew")
    ~~~~~~~~~~~~~~~~~~~~~~~~~~~~~~^^^^^^^^^^^^^^^^^^^^^^^^^^^^^^^^
  File "C:\Users\Utilisateur\AppData\Local\Programs\Python\Python313\Lib\tkinter\__init__.py", line 2699, in grid_configure
    self.tk.call(
    ~~~~~~~~~~~~^
          ('grid', 'configure', self._w)
          ^^^^^^^^^^^^^^^^^^^^^^^^^^^^^^
          + self._options(cnf, kw))
          ^^^^^^^^^^^^^^^^^^^^^^^^^
_tkinter.TclError: cannot use geometry manager grid inside .!frame3.!frame5.!notebook.!frame4 which already has slaves managed by pack
----------------------------------------
Rapport d'erreur - 2025-08-23 18:45:40
Message: Failed to check for updates
Erreur: HTTP Error 404: Not Found
Traceback:
Traceback (most recent call last):
  File "c:\Users\Utilisateur\Desktop\jeux en python\lancer1.py", line 2830, in _check_for_updates_worker
    with urllib.request.urlopen(UPDATE_URL, timeout=10) as response:
         ~~~~~~~~~~~~~~~~~~~~~~^^^^^^^^^^^^^^^^^^^^^^^^
  File "C:\Users\Utilisateur\AppData\Local\Programs\Python\Python313\Lib\urllib\request.py", line 189, in urlopen
    return opener.open(url, data, timeout)
           ~~~~~~~~~~~^^^^^^^^^^^^^^^^^^^^
  File "C:\Users\Utilisateur\AppData\Local\Programs\Python\Python313\Lib\urllib\request.py", line 495, in open
    response = meth(req, response)
  File "C:\Users\Utilisateur\AppData\Local\Programs\Python\Python313\Lib\urllib\request.py", line 604, in http_response
    response = self.parent.error(
        'http', request, response, code, msg, hdrs)
  File "C:\Users\Utilisateur\AppData\Local\Programs\Python\Python313\Lib\urllib\request.py", line 533, in error
    return self._call_chain(*args)
           ~~~~~~~~~~~~~~~~^^^^^^^
  File "C:\Users\Utilisateur\AppData\Local\Programs\Python\Python313\Lib\urllib\request.py", line 466, in _call_chain
    result = func(*args)
  File "C:\Users\Utilisateur\AppData\Local\Programs\Python\Python313\Lib\urllib\request.py", line 613, in http_error_default
    raise HTTPError(req.full_url, code, msg, hdrs, fp)
urllib.error.HTTPError: HTTP Error 404: Not Found
----------------------------------------
Rapport d'erreur - 2025-08-23 18:46:00
Message: Failed to check for updates
Erreur: HTTP Error 404: Not Found
Traceback:
Traceback (most recent call last):
  File "c:\Users\Utilisateur\Desktop\jeux en python\lancer1.py", line 2830, in _check_for_updates_worker
    with urllib.request.urlopen(UPDATE_URL, timeout=10) as response:
         ~~~~~~~~~~~~~~~~~~~~~~^^^^^^^^^^^^^^^^^^^^^^^^
  File "C:\Users\Utilisateur\AppData\Local\Programs\Python\Python313\Lib\urllib\request.py", line 189, in urlopen
    return opener.open(url, data, timeout)
           ~~~~~~~~~~~^^^^^^^^^^^^^^^^^^^^
  File "C:\Users\Utilisateur\AppData\Local\Programs\Python\Python313\Lib\urllib\request.py", line 495, in open
    response = meth(req, response)
  File "C:\Users\Utilisateur\AppData\Local\Programs\Python\Python313\Lib\urllib\request.py", line 604, in http_response
    response = self.parent.error(
        'http', request, response, code, msg, hdrs)
  File "C:\Users\Utilisateur\AppData\Local\Programs\Python\Python313\Lib\urllib\request.py", line 533, in error
    return self._call_chain(*args)
           ~~~~~~~~~~~~~~~~^^^^^^^
  File "C:\Users\Utilisateur\AppData\Local\Programs\Python\Python313\Lib\urllib\request.py", line 466, in _call_chain
    result = func(*args)
  File "C:\Users\Utilisateur\AppData\Local\Programs\Python\Python313\Lib\urllib\request.py", line 613, in http_error_default
    raise HTTPError(req.full_url, code, msg, hdrs, fp)
urllib.error.HTTPError: HTTP Error 404: Not Found
----------------------------------------
Rapport d'erreur - 2025-08-23 18:50:25
Message: L'application a rencontré une erreur fatale et va se fermer.
Erreur: type object 'StyleBuilderTTK' has no attribute 'create_menu_style'
Traceback:
Traceback (most recent call last):
  File "c:\Users\Utilisateur\Desktop\jeux en python\lancer1.py", line 3528, in <module>
    app = GameLauncher()
  File "c:\Users\Utilisateur\Desktop\jeux en python\lancer1.py", line 354, in __init__
    self._init_styles()
    ~~~~~~~~~~~~~~~~~^^
  File "c:\Users\Utilisateur\Desktop\jeux en python\lancer1.py", line 906, in _init_styles
    self.app_style.configure("Menubar.TFrame", background="#212529")
    ~~~~~~~~~~~~~~~~~~~~~~~~^^^^^^^^^^^^^^^^^^^^^^^^^^^^^^^^^^^^^^^^
  File "C:\Users\Utilisateur\AppData\Local\Programs\Python\Python313\Lib\site-packages\ttkbootstrap\style.py", line 578, in configure
    ttkstyle = Bootstyle.update_ttk_widget_style(None, style)
  File "C:\Users\Utilisateur\AppData\Local\Programs\Python\Python313\Lib\site-packages\ttkbootstrap\style.py", line 5295, in update_ttk_widget_style
    builder_method = builder.name_to_method(method_name)
  File "C:\Users\Utilisateur\AppData\Local\Programs\Python\Python313\Lib\site-packages\ttkbootstrap\style.py", line 1241, in name_to_method
    func = getattr(StyleBuilderTTK, method_name)
AttributeError: type object 'StyleBuilderTTK' has no attribute 'create_menu_style'. Did you mean: 'create_entry_style'?
----------------------------------------
Rapport d'erreur - 2025-08-23 18:53:11
Message: Failed to check for updates
Erreur: HTTP Error 404: Not Found
Traceback:
Traceback (most recent call last):
  File "c:\Users\Utilisateur\Desktop\jeux en python\lancer1.py", line 3014, in _check_for_updates_worker
    with urllib.request.urlopen(UPDATE_URL, timeout=10) as response:
         ~~~~~~~~~~~~~~~~~~~~~~^^^^^^^^^^^^^^^^^^^^^^^^
  File "C:\Users\Utilisateur\AppData\Local\Programs\Python\Python313\Lib\urllib\request.py", line 189, in urlopen
    return opener.open(url, data, timeout)
           ~~~~~~~~~~~^^^^^^^^^^^^^^^^^^^^
  File "C:\Users\Utilisateur\AppData\Local\Programs\Python\Python313\Lib\urllib\request.py", line 495, in open
    response = meth(req, response)
  File "C:\Users\Utilisateur\AppData\Local\Programs\Python\Python313\Lib\urllib\request.py", line 604, in http_response
    response = self.parent.error(
        'http', request, response, code, msg, hdrs)
  File "C:\Users\Utilisateur\AppData\Local\Programs\Python\Python313\Lib\urllib\request.py", line 533, in error
    return self._call_chain(*args)
           ~~~~~~~~~~~~~~~~^^^^^^^
  File "C:\Users\Utilisateur\AppData\Local\Programs\Python\Python313\Lib\urllib\request.py", line 466, in _call_chain
    result = func(*args)
  File "C:\Users\Utilisateur\AppData\Local\Programs\Python\Python313\Lib\urllib\request.py", line 613, in http_error_default
    raise HTTPError(req.full_url, code, msg, hdrs, fp)
urllib.error.HTTPError: HTTP Error 404: Not Found
----------------------------------------
Rapport d'erreur - 2025-08-23 18:55:26
Message: Failed to check for updates
Erreur: HTTP Error 404: Not Found
Traceback:
Traceback (most recent call last):
  File "c:\Users\Utilisateur\Desktop\jeux en python\lancer1.py", line 3016, in _check_for_updates_worker
    with urllib.request.urlopen(UPDATE_URL, timeout=10) as response:
         ~~~~~~~~~~~~~~~~~~~~~~^^^^^^^^^^^^^^^^^^^^^^^^
  File "C:\Users\Utilisateur\AppData\Local\Programs\Python\Python313\Lib\urllib\request.py", line 189, in urlopen
    return opener.open(url, data, timeout)
           ~~~~~~~~~~~^^^^^^^^^^^^^^^^^^^^
  File "C:\Users\Utilisateur\AppData\Local\Programs\Python\Python313\Lib\urllib\request.py", line 495, in open
    response = meth(req, response)
  File "C:\Users\Utilisateur\AppData\Local\Programs\Python\Python313\Lib\urllib\request.py", line 604, in http_response
    response = self.parent.error(
        'http', request, response, code, msg, hdrs)
  File "C:\Users\Utilisateur\AppData\Local\Programs\Python\Python313\Lib\urllib\request.py", line 533, in error
    return self._call_chain(*args)
           ~~~~~~~~~~~~~~~~^^^^^^^
  File "C:\Users\Utilisateur\AppData\Local\Programs\Python\Python313\Lib\urllib\request.py", line 466, in _call_chain
    result = func(*args)
  File "C:\Users\Utilisateur\AppData\Local\Programs\Python\Python313\Lib\urllib\request.py", line 613, in http_error_default
    raise HTTPError(req.full_url, code, msg, hdrs, fp)
urllib.error.HTTPError: HTTP Error 404: Not Found
----------------------------------------
